<?xml version="1.0" ?>
<!-- =================================================================================== -->
<!-- |    This document was autogenerated by xacro from robot.xacro                    | -->
<!-- |    EDITING THIS FILE BY HAND IS NOT RECOMMENDED                                 | -->
<!-- =================================================================================== -->
<robot name="wheel_quadruped_arm_robot">
    <material name="black">
        <color rgba="0.0 0.0 0.0 1.0"/>
    </material>
    <material name="blue">
        <color rgba="0.0 0.0 0.8 1.0"/>
    </material>
    <material name="green">
        <color rgba="0.0 0.8 0.0 1.0"/>
    </material>
    <material name="grey">
        <color rgba="0.2 0.2 0.2 1.0"/>
    </material>
    <material name="silver">
        <color rgba="0.9137254901960784 0.9137254901960784 0.8470588235294118 1.0"/>
    </material>
    <material name="orange">
        <color rgba="1.0 0.4235294117647059 0.0392156862745098 1.0"/>
    </material>
    <material name="brown">
        <color rgba="0.8705882352941177 0.8117647058823529 0.7647058823529411 1.0"/>
    </material>
    <material name="red">
        <color rgba="0.8 0.0 0.0 1.0"/>
    </material>
    <material name="white">
        <color rgba="1.0 1.0 1.0 1.0"/>
    </material>
    <!-- ros_control plugin -->
    <gazebo>
        <plugin filename="liblegged_hw_sim.so" name="gazebo_ros_control">
            <robotNamespace>/</robotNamespace>
            <robotParam>wheel_quadruped_arm_robot_description</robotParam>
            <robotSimType>legged_gazebo/LeggedHWSim</robotSimType>
        </plugin>
    </gazebo>
    <gazebo>
        <plugin filename="libgazebo_ros_p3d.so" name="p3d_base_controller">
            <alwaysOn>true</alwaysOn>
            <updateRate>1000.0</updateRate>
            <bodyName>base</bodyName>
            <topicName>Odometry</topicName>
            <gaussianNoise>0</gaussianNoise>
            <frameName>world</frameName>
            <xyzOffsets>0 0 0</xyzOffsets>
            <rpyOffsets>0 0 0</rpyOffsets>
        </plugin>
    </gazebo>
    <gazebo reference="base_link">
        <maxVel>100.</maxVel>
        <kp>10000.</kp>
        <kd>0.</kd>
    </gazebo>
    <gazebo reference="stick_link">
        <mu1>0.2</mu1>
        <mu2>0.2</mu2>
        <material>Gazebo/White</material>
    </gazebo>
    <!-- LF leg -->
    <gazebo reference="LF_hip">
        <mu1>0.2</mu1>
        <mu2>0.2</mu2>
        <material>Gazebo/DarkGrey</material>
    </gazebo>
    <gazebo reference="LF_thigh">
        <mu1>0.2</mu1>
        <mu2>0.2</mu2>
        <self_collide>0</self_collide>
        <material>Gazebo/DarkGrey</material>
        <kp value="1000000.0"/>
        <kd value="1.0"/>
    </gazebo>
    <gazebo reference="LF_calf">
        <mu1>0.2</mu1>
        <mu2>0.2</mu2>
        <self_collide>1</self_collide>
    </gazebo>
    <gazebo reference="LF_wheel">
        <mu1>0.6</mu1>
        <mu2>0.6</mu2>
        <self_collide>1</self_collide>
        <material>Gazebo/DarkGrey</material>
        <kp value="1000000.0"/>
        <kd value="1.0"/>
    </gazebo>
    <!-- RF leg -->
    <gazebo reference="RF_hip">
        <mu1>0.2</mu1>
        <mu2>0.2</mu2>
        <material>Gazebo/DarkGrey</material>
    </gazebo>
    <gazebo reference="RF_thigh">
        <mu1>0.2</mu1>
        <mu2>0.2</mu2>
        <self_collide>0</self_collide>
        <material>Gazebo/DarkGrey</material>
        <kp value="1000000.0"/>
        <kd value="1.0"/>
    </gazebo>
    <gazebo reference="RF_calf">
        <mu1>0.2</mu1>
        <mu2>0.2</mu2>
        <self_collide>1</self_collide>
    </gazebo>
    <gazebo reference="RF_wheel">
        <mu1>0.6</mu1>
        <mu2>0.6</mu2>
        <self_collide>1</self_collide>
        <material>Gazebo/DarkGrey</material>
        <kp value="1000000.0"/>
        <kd value="1.0"/>
    </gazebo>
    <!-- LH leg -->
    <gazebo reference="LH_hip">
        <mu1>0.2</mu1>
        <mu2>0.2</mu2>
        <material>Gazebo/DarkGrey</material>
    </gazebo>
    <gazebo reference="LH_thigh">
        <mu1>0.2</mu1>
        <mu2>0.2</mu2>
        <self_collide>0</self_collide>
        <material>Gazebo/DarkGrey</material>
        <kp value="1000000.0"/>
        <kd value="1.0"/>
    </gazebo>
    <gazebo reference="LH_calf">
        <mu1>0.2</mu1>
        <mu2>0.2</mu2>
        <self_collide>1</self_collide>
    </gazebo>
    <gazebo reference="LH_wheel">
        <mu1>0.6</mu1>
        <mu2>0.6</mu2>
        <self_collide>1</self_collide>
        <material>Gazebo/DarkGrey</material>
        <kp value="1000000.0"/>
        <kd value="1.0"/>
    </gazebo>
    <!-- RH leg -->
    <gazebo reference="RH_hip">
        <mu1>0.2</mu1>
        <mu2>0.2</mu2>
        <material>Gazebo/DarkGrey</material>
    </gazebo>
    <gazebo reference="RH_thigh">
        <mu1>0.2</mu1>
        <mu2>0.2</mu2>
        <self_collide>0</self_collide>
        <material>Gazebo/DarkGrey</material>
        <kp value="1000000.0"/>
        <kd value="1.0"/>
    </gazebo>
    <gazebo reference="RH_calf">
        <mu1>0.2</mu1>
        <mu2>0.2</mu2>
        <self_collide>1</self_collide>
    </gazebo>
    <gazebo reference="RH_wheel">
        <mu1>0.6</mu1>
        <mu2>0.6</mu2>
        <self_collide>1</self_collide>
        <material>Gazebo/DarkGrey</material>
        <kp value="1000000.0"/>
        <kd value="1.0"/>
    </gazebo>
    <!-- limx arm -->
    <gazebo reference="limx_arm">
        <mu1>0.2</mu1>
        <mu2>0.2</mu2>
        <self_collide>1</self_collide>
        <material>Gazebo/DarkGrey</material>
    </gazebo>
    <gazebo reference="L1">
        <mu1>0.2</mu1>
        <mu2>0.2</mu2>
        <self_collide>1</self_collide>
        <material>Gazebo/DarkGrey</material>
    </gazebo>
    <gazebo reference="L2">
        <mu1>0.2</mu1>
        <mu2>0.2</mu2>
        <material>Gazebo/DarkGrey</material>
        <self_collide>1</self_collide>
    </gazebo>
    <gazebo reference="L3">
        <mu1>0.2</mu1>
        <mu2>0.2</mu2>
        <self_collide>1</self_collide>
        <material>Gazebo/DarkGrey</material>
    </gazebo>
    <gazebo reference="L4">
        <mu1>0.2</mu1>
        <mu2>0.2</mu2>
        <self_collide>1</self_collide>
        <material>Gazebo/DarkGrey</material>
    </gazebo>
    <gazebo reference="L5">
        <mu1>0.2</mu1>
        <mu2>0.2</mu2>
        <self_collide>1</self_collide>
        <material>Gazebo/DarkGrey</material>
    </gazebo>
    <gazebo reference="L6">
        <mu1>0.2</mu1>
        <mu2>0.2</mu2>
        <self_collide>1</self_collide>
        <material>Gazebo/DarkGrey</material>
    </gazebo>

    <link name="fixed_world"/>
    <joint name="fixed_base" type="fixed">
        <parent link="fixed_world"/>
        <child link="base"/>
        <origin rpy="0 0 0" xyz="0 0 0.5"/>
    </joint>

    <link name="base">
        <visual>
            <origin rpy="0 0 0" xyz="-0.0455 0 -0.07551"/>
            <geometry>
                <mesh filename="../meshes/wheel_quadruped/base_link.STL"
                      scale="1 1 1"/>
            </geometry>
            <material name="orange">
                <color rgba="0.752941176470588 0.752941176470588 0.752941176470588 1"/>
            </material>
        </visual>
        <collision>
            <origin rpy="0 0 0" xyz="-0.0455 0 -0.07551"/>
            <geometry>
                <box size="0.515 0.2635 0.151"/>
            </geometry>
        </collision>
        <inertial>
            <origin rpy="0 0 0" xyz="-0.042248 0.000914 -0.089046"/>
            <mass value="20.597"/>
            <inertia ixx="0.149401525" ixy="-0.000608481" ixz="0.011793831" iyy="0.735245026" iyz="-3.821e-06"
                     izz="0.770371789"/>
        </inertial>
    </link>
    <!-- Imu is fixed to the base link -->
    <joint name="limx_imu_joint" type="fixed">
        <origin rpy="0. 0. 0." xyz="0. 0. 0."/>
        <parent link="base"/>
        <child link="limx_imu"/>
    </joint>
    <!-- Imu link -->
    <link name="limx_imu">
        <inertial>
            <mass value="0.01"/>
            <origin rpy="0 0 0" xyz="0 0 0"/>
            <inertia ixx="0.000001" ixy="0" ixz="0" iyy="0.000001" iyz="0" izz="0.000001"/>
        </inertial>
        <visual>
            <origin rpy="0 0 0" xyz="0 0 0"/>
            <geometry>
                <box size="0.015 0.015 0.004"/>
            </geometry>
        </visual>
        <material name="orange">
            <color rgba="255 108 10 255"/>
        </material>
    </link>
    <gazebo reference="limx_imu">
        <material>Gazebo/Orange</material>
    </gazebo>
    <gazebo reference="limx_imu_joint">
        <disableFixedJointLumping>true</disableFixedJointLumping>
    </gazebo>

    <joint name="support_joint1" type="fixed">
        <origin rpy="0. 0. 0." xyz="0.15 0.1 -0.3"/>
        <parent link="base"/>
        <child link="support1"/>
    </joint>
    <!-- &lt;!&ndash; support link &ndash;&gt; -->
    <link name="support1">
        <collision>
            <origin rpy="0 0 0" xyz="0 0 0"/>
            <geometry>
                <box size="0.015 0.015 0.004"/>
            </geometry>
        </collision>
    </link>
    <joint name="support_joint2" type="fixed">
        <origin rpy="0. 0. 0." xyz="-0.25 0.1 -0.3"/>
        <parent link="base"/>
        <child link="support2"/>
    </joint>
    <!-- &lt;!&ndash; support link &ndash;&gt; -->
    <link name="support2">
        <collision>
            <origin rpy="0 0 0" xyz="0 0 0"/>
            <geometry>
                <box size="0.015 0.015 0.004"/>
            </geometry>
        </collision>
    </link>
    <joint name="support_joint3" type="fixed">
        <origin rpy="0. 0. 0." xyz="0.15 -0.1 -0.3"/>
        <parent link="base"/>
        <child link="support3"/>
    </joint>
    <!-- &lt;!&ndash; support link &ndash;&gt; -->
    <link name="support3">
        <collision>
            <origin rpy="0 0 0" xyz="0 0 0"/>
            <geometry>
                <box size="0.015 0.015 0.004"/>
            </geometry>
        </collision>
    </link>
    <joint name="support_joint4" type="fixed">
        <origin rpy="0. 0. 0." xyz="-0.25 -0.1 -0.3"/>
        <parent link="base"/>
        <child link="support4"/>
    </joint>
    <!--    &lt;!&ndash; support link &ndash;&gt;-->
    <link name="support4">
        <collision>
            <origin rpy="0 0 0" xyz="0 0 0"/>
            <geometry>
                <box size="0.015 0.015 0.004"/>
            </geometry>
        </collision>
    </link>


    <joint name="LF_HAA" type="revolute">
        <origin rpy="0 0 0" xyz="0.216 0.065 -0.07376"/>
        <!-- <origin xyz="${HAA_offset_x*front_hind} ${HAA_offset_y*left_right} ${HAA_offset_z}" rpy="0 0 0"/> -->
        <parent link="base"/>
        <child link="LF_hip"/>
        <axis xyz="1 0 0"/>
        <dynamics damping="0.05" friction="0.01"/>
        <limit effort="60" lower="-0.87" upper="0.87" velocity="20"/>
    </joint>
    <link name="LF_hip">
        <visual>
            <origin rpy="0 0 0" xyz="0 0 0"/>
            <geometry>
                <mesh filename="../meshes/wheel_quadruped/LF_hip.STL" scale="1 1 1"/>
            </geometry>
            <material name="orange"/>
            <color rgba="0.8902 0.8902 0.91373 1"/>
        </visual>
        <!-- <collision>
                    <origin rpy="${pi/2.0} 0 0" xyz="0 0 0"/>
                    <geometry>
                        <cylinder length="${hip_length}" radius="${hip_radius}"/>
                    </geometry>
                </collision> -->
        <inertial>
            <origin rpy="0 0 0" xyz="0.058399 0.001551 9e-06"/>
            <mass value="1.06"/>
            <inertia ixx="0.001012701" ixy="1.0667e-05" ixz="-2.91e-07" iyy="0.001889263" iyz="2.19e-07"
                     izz="0.00148239"/>
        </inertial>
    </link>
    <joint name="LF_HFE" type="revolute">
        <origin rpy="0 0 0" xyz="0.0693 0.02715 0"/>
        <parent link="LF_hip"/>
        <child link="LF_thigh"/>
        <axis xyz="0 1 0"/>
        <dynamics damping="0.05" friction="0.01"/>
        <limit effort="60" lower="-2.27" upper="1.22" velocity="20"/>
    </joint>
    <link name="LF_thigh">
        <visual>
            <origin rpy="0 0 0" xyz="0 0 0"/>
            <geometry>
                <mesh filename="../meshes/wheel_quadruped/LF_thigh.STL"
                      scale="1 1 1"/>
            </geometry>
            <material name="orange"/>
            <color rgba="0.8902 0.8902 0.91373 1"/>
        </visual>
        <!-- <collision>
                    <origin rpy="0 ${pi/2.0+0.1} 0" xyz="${thigh_x_offset} 0 ${-thigh_length/2.0}"/>
                    <geometry>
                        <box size="${thigh_length} ${thigh_width} ${thigh_height}"/>
                    </geometry>
                </collision>
                <collision>
                    <origin rpy="${pi/2.0} 0 0" xyz="0 ${left_right*thigh_shoulder_y_offset} 0"/>
                    <geometry>
                        <cylinder length="${thigh_shoulder_length}" radius="${thigh_shoulder_radius}"/>
                    </geometry>
                </collision> -->
        <inertial>
            <origin rpy="0 0 0" xyz="-0.063927 0.057242 0.004729"/>
            <mass value="2.13"/>
            <inertia ixx="0.003260617" ixy="0.003296633" ixz="0.001182035" iyy="0.024261326" iyz="-0.000279689"
                     izz="0.024745032"/>
        </inertial>
    </link>
    <joint name="LF_KFE" type="revolute">
        <origin rpy="0 0 0" xyz="-0.28 0.0797 0"/>
        <parent link="LF_thigh"/>
        <child link="LF_calf"/>
        <axis xyz="0 1 0"/>
        <dynamics damping="0.05" friction="0.01"/>
        <limit effort="60" lower="0.0" upper="1.95476876223365" velocity="20"/>
    </joint>
    <link name="LF_calf">
        <visual>
            <origin rpy="0 0 0" xyz="0 0 0"/>
            <geometry>
                <mesh filename="../meshes/wheel_quadruped/LF_calf.STL" scale="1 1 1"/>
            </geometry>
            <material name="orange"/>
            <color rgba="0.20392 0.20392 0.20392 1"/>
        </visual>
        <collision>
            <origin rpy="0 0.680678408 0" xyz="0.10876 0 -0.08805"/>
            <geometry>
                <box size="0.28 0.023 0.0451"/>
            </geometry>
        </collision>
        <inertial>
            <origin rpy="0 0 0" xyz="0.182894 0.004783 -0.111716"/>
            <mass value="1.123"/>
            <inertia ixx="0.00440324" ixy="-0.000291175" ixz="0.005566403" iyy="0.013523185" iyz="0.000203833"
                     izz="0.009572209"/>
        </inertial>
    </link>
    <joint name="LF_WHL" type="revolute">
        <origin rpy="0 0 0" xyz="0.21441 0.03231 -0.17987"/>
        <parent link="LF_calf"/>
        <child link="LF_wheel"/>
        <axis xyz="0 1 0"/>
        <limit effort="20" lower="-1000" upper="1000" velocity="20"/>
        <dynamics friction="0.1"/>
    </joint>
    <!-- <gazebo reference="${prefix}_WHL">
              <disableFixedJointLumping>true</disableFixedJointLumping>
          </gazebo> -->
    <link name="LF_wheel">
        <visual>
            <origin rpy="0 0 0" xyz="0 0 0"/>
            <geometry>
                <mesh filename="../meshes/wheel_quadruped/LF_wheel.STL"
                      scale="1 1 1"/>
            </geometry>
            <material name="orange"/>
            <color rgba="0.69804 0.69804 0.69804 1"/>
        </visual>
        <collision>
            <origin rpy="1.5707963267948966 0 0" xyz="0 0 0"/>
            <geometry>
                <cylinder length="0.05" radius="0.127"/>
            </geometry>
        </collision>
        <inertial>
            <origin rpy="0 0 0" xyz="7.7e-05 0.001028 -3.3e-05"/>
            <mass value="0.707"/>
            <inertia ixx="0.003059642" ixy="5.1e-08" ixz="-4.28e-07" iyy="0.005866966" iyz="-3.5e-08"
                     izz="0.003063384"/>
        </inertial>
    </link>
    <transmission name="LF_HAA_tran">
        <type>transmission_interface/SimpleTransmission</type>
        <joint name="LF_HAA">
            <hardwareInterface>hardware_interface/EffortJointInterface</hardwareInterface>
        </joint>
        <actuator name="LF_HAA_motor">
            <hardwareInterface>hardware_interface/EffortJointInterface</hardwareInterface>
            <mechanicalReduction>1</mechanicalReduction>
        </actuator>
    </transmission>
    <transmission name="LF_HFE_tran">
        <type>transmission_interface/SimpleTransmission</type>
        <joint name="LF_HFE">
            <hardwareInterface>hardware_interface/EffortJointInterface</hardwareInterface>
        </joint>
        <actuator name="LF_HFE_motor">
            <hardwareInterface>hardware_interface/EffortJointInterface</hardwareInterface>
            <mechanicalReduction>1</mechanicalReduction>
        </actuator>
    </transmission>
    <transmission name="LF_KFE_tran">
        <type>transmission_interface/SimpleTransmission</type>
        <joint name="LF_KFE">
            <hardwareInterface>hardware_interface/EffortJointInterface</hardwareInterface>
        </joint>
        <actuator name="LF_KFE_motor">
            <hardwareInterface>hardware_interface/EffortJointInterface</hardwareInterface>
            <mechanicalReduction>1</mechanicalReduction>
        </actuator>
    </transmission>
    <transmission name="LF_WHL_tran">
        <type>transmission_interface/SimpleTransmission</type>
        <joint name="LF_WHL">
            <hardwareInterface>hardware_interface/EffortJointInterface</hardwareInterface>
        </joint>
        <actuator name="LF_WHL_motor">
            <hardwareInterface>hardware_interface/EffortJointInterface</hardwareInterface>
            <mechanicalReduction>1</mechanicalReduction>
        </actuator>
    </transmission>
    <joint name="RF_HAA" type="revolute">
        <origin rpy="0 0 0" xyz="0.216 -0.065 -0.07376"/>
        <!-- <origin xyz="${HAA_offset_x*front_hind} ${HAA_offset_y*left_right} ${HAA_offset_z}" rpy="0 0 0"/> -->
        <parent link="base"/>
        <child link="RF_hip"/>
        <axis xyz="1 0 0"/>
        <dynamics damping="0.05" friction="0.01"/>
        <limit effort="60" lower="-0.87" upper="0.87" velocity="20"/>
    </joint>
    <link name="RF_hip">
        <visual>
            <origin rpy="0 0 0" xyz="0 0 0"/>
            <geometry>
                <mesh filename="../meshes/wheel_quadruped/RF_hip.STL" scale="1 1 1"/>
            </geometry>
            <material name="orange"/>
            <color rgba="0.8902 0.8902 0.91373 1"/>
        </visual>
        <!-- <collision>
                    <origin rpy="${pi/2.0} 0 0" xyz="0 0 0"/>
                    <geometry>
                        <cylinder length="${hip_length}" radius="${hip_radius}"/>
                    </geometry>
                </collision> -->
        <inertial>
            <origin rpy="0 0 0" xyz="0.058399 -0.001551 9e-06"/>
            <mass value="1.06"/>
            <inertia ixx="0.001012701" ixy="-1.0667e-05" ixz="-2.91e-07" iyy="0.001889263" iyz="-2.19e-07"
                     izz="0.00148239"/>
        </inertial>
    </link>
    <joint name="RF_HFE" type="revolute">
        <origin rpy="0 0 0" xyz="0.0693 -0.02715 0"/>
        <parent link="RF_hip"/>
        <child link="RF_thigh"/>
        <axis xyz="0 1 0"/>
        <dynamics damping="0.05" friction="0.01"/>
        <limit effort="60" lower="-2.27" upper="1.22" velocity="20"/>
    </joint>
    <link name="RF_thigh">
        <visual>
            <origin rpy="0 0 0" xyz="0 0 0"/>
            <geometry>
                <mesh filename="../meshes/wheel_quadruped/RF_thigh.STL"
                      scale="1 1 1"/>
            </geometry>
            <material name="orange"/>
            <color rgba="0.8902 0.8902 0.91373 1"/>
        </visual>
        <!-- <collision>
                    <origin rpy="0 ${pi/2.0+0.1} 0" xyz="${thigh_x_offset} 0 ${-thigh_length/2.0}"/>
                    <geometry>
                        <box size="${thigh_length} ${thigh_width} ${thigh_height}"/>
                    </geometry>
                </collision>
                <collision>
                    <origin rpy="${pi/2.0} 0 0" xyz="0 ${left_right*thigh_shoulder_y_offset} 0"/>
                    <geometry>
                        <cylinder length="${thigh_shoulder_length}" radius="${thigh_shoulder_radius}"/>
                    </geometry>
                </collision> -->
        <inertial>
            <origin rpy="0 0 0" xyz="-0.063927 -0.057242 0.004729"/>
            <mass value="2.13"/>
            <inertia ixx="0.003260617" ixy="-0.003296633" ixz="0.001182035" iyy="0.024261326" iyz="0.000279689"
                     izz="0.024745032"/>
        </inertial>
    </link>
    <joint name="RF_KFE" type="revolute">
        <origin rpy="0 0 0" xyz="-0.28 -0.0797 0"/>
        <parent link="RF_thigh"/>
        <child link="RF_calf"/>
        <axis xyz="0 1 0"/>
        <dynamics damping="0.05" friction="0.01"/>
        <limit effort="60" lower="0.0" upper="1.95476876223365" velocity="20"/>
    </joint>
    <link name="RF_calf">
        <visual>
            <origin rpy="0 0 0" xyz="0 0 0"/>
            <geometry>
                <mesh filename="../meshes/wheel_quadruped/RF_calf.STL" scale="1 1 1"/>
            </geometry>
            <material name="orange"/>
            <color rgba="0.20392 0.20392 0.20392 1"/>
        </visual>
        <collision>
            <origin rpy="0 0.680678408 0" xyz="0.10876 0 -0.08805"/>
            <geometry>
                <box size="0.28 0.023 0.0451"/>
            </geometry>
        </collision>
        <inertial>
            <origin rpy="0 0 0" xyz="0.182894 -0.004783 -0.111716"/>
            <mass value="1.123"/>
            <inertia ixx="0.00440324" ixy="0.000291175" ixz="0.005566403" iyy="0.013523185" iyz="-0.000203833"
                     izz="0.009572209"/>
        </inertial>
    </link>
    <joint name="RF_WHL" type="revolute">
        <origin rpy="0 0 0" xyz="0.21441 -0.03231 -0.17987"/>
        <parent link="RF_calf"/>
        <child link="RF_wheel"/>
        <axis xyz="0 1 0"/>
        <limit effort="20" lower="-1000" upper="1000" velocity="20"/>
        <dynamics friction="0.1"/>
    </joint>
    <!-- <gazebo reference="${prefix}_WHL">
              <disableFixedJointLumping>true</disableFixedJointLumping>
          </gazebo> -->
    <link name="RF_wheel">
        <visual>
            <origin rpy="0 0 0" xyz="0 0 0"/>
            <geometry>
                <mesh filename="../meshes/wheel_quadruped/RF_wheel.STL"
                      scale="1 1 1"/>
            </geometry>
            <material name="orange"/>
            <color rgba="0.69804 0.69804 0.69804 1"/>
        </visual>
        <collision>
            <origin rpy="1.5707963267948966 0 0" xyz="0 0 0"/>
            <geometry>
                <cylinder length="0.05" radius="0.127"/>
            </geometry>
        </collision>
        <inertial>
            <origin rpy="0 0 0" xyz="7.7e-05 -0.001028 -3.3e-05"/>
            <mass value="0.707"/>
            <inertia ixx="0.003059642" ixy="-5.1e-08" ixz="-4.28e-07" iyy="0.005866966" iyz="3.5e-08"
                     izz="0.003063384"/>
        </inertial>
    </link>
    <transmission name="RF_HAA_tran">
        <type>transmission_interface/SimpleTransmission</type>
        <joint name="RF_HAA">
            <hardwareInterface>hardware_interface/EffortJointInterface</hardwareInterface>
        </joint>
        <actuator name="RF_HAA_motor">
            <hardwareInterface>hardware_interface/EffortJointInterface</hardwareInterface>
            <mechanicalReduction>1</mechanicalReduction>
        </actuator>
    </transmission>
    <transmission name="RF_HFE_tran">
        <type>transmission_interface/SimpleTransmission</type>
        <joint name="RF_HFE">
            <hardwareInterface>hardware_interface/EffortJointInterface</hardwareInterface>
        </joint>
        <actuator name="RF_HFE_motor">
            <hardwareInterface>hardware_interface/EffortJointInterface</hardwareInterface>
            <mechanicalReduction>1</mechanicalReduction>
        </actuator>
    </transmission>
    <transmission name="RF_KFE_tran">
        <type>transmission_interface/SimpleTransmission</type>
        <joint name="RF_KFE">
            <hardwareInterface>hardware_interface/EffortJointInterface</hardwareInterface>
        </joint>
        <actuator name="RF_KFE_motor">
            <hardwareInterface>hardware_interface/EffortJointInterface</hardwareInterface>
            <mechanicalReduction>1</mechanicalReduction>
        </actuator>
    </transmission>
    <transmission name="RF_WHL_tran">
        <type>transmission_interface/SimpleTransmission</type>
        <joint name="RF_WHL">
            <hardwareInterface>hardware_interface/EffortJointInterface</hardwareInterface>
        </joint>
        <actuator name="RF_WHL_motor">
            <hardwareInterface>hardware_interface/EffortJointInterface</hardwareInterface>
            <mechanicalReduction>1</mechanicalReduction>
        </actuator>
    </transmission>
    <joint name="LH_HAA" type="revolute">
        <origin rpy="0 0 0" xyz="-0.307 0.065 -0.07376"/>
        <!-- <origin xyz="${HAA_offset_x*front_hind} ${HAA_offset_y*left_right} ${HAA_offset_z}" rpy="0 0 0"/> -->
        <parent link="base"/>
        <child link="LH_hip"/>
        <axis xyz="1 0 0"/>
        <dynamics damping="0.05" friction="0.01"/>
        <limit effort="60" lower="-0.87" upper="0.87" velocity="20"/>
    </joint>
    <link name="LH_hip">
        <visual>
            <origin rpy="0 0 0" xyz="0 0 0"/>
            <geometry>
                <mesh filename="../meshes/wheel_quadruped/LH_hip.STL" scale="1 1 1"/>
            </geometry>
            <material name="orange"/>
            <color rgba="0.8902 0.8902 0.91373 1"/>
        </visual>
        <!-- <collision>
                    <origin rpy="${pi/2.0} 0 0" xyz="0 0 0"/>
                    <geometry>
                        <cylinder length="${hip_length}" radius="${hip_radius}"/>
                    </geometry>
                </collision> -->
        <inertial>
            <origin rpy="0 0 0" xyz="-0.058399 0.001551 9e-06"/>
            <mass value="1.06"/>
            <inertia ixx="0.001012701" ixy="-1.0667e-05" ixz="2.91e-07" iyy="0.001889263" iyz="2.19e-07"
                     izz="0.00148239"/>
        </inertial>
    </link>
    <joint name="LH_HFE" type="revolute">
        <origin rpy="0 0 0" xyz="-0.0693 0.02715 0"/>
        <parent link="LH_hip"/>
        <child link="LH_thigh"/>
        <axis xyz="0 1 0"/>
        <dynamics damping="0.05" friction="0.01"/>
        <limit effort="60" lower="-2.27" upper="1.22" velocity="20"/>
    </joint>
    <link name="LH_thigh">
        <visual>
            <origin rpy="0 0 0" xyz="0 0 0"/>
            <geometry>
                <mesh filename="../meshes/wheel_quadruped/LH_thigh.STL"
                      scale="1 1 1"/>
            </geometry>
            <material name="orange"/>
            <color rgba="0.8902 0.8902 0.91373 1"/>
        </visual>
        <!-- <collision>
                    <origin rpy="0 ${pi/2.0+0.1} 0" xyz="${thigh_x_offset} 0 ${-thigh_length/2.0}"/>
                    <geometry>
                        <box size="${thigh_length} ${thigh_width} ${thigh_height}"/>
                    </geometry>
                </collision>
                <collision>
                    <origin rpy="${pi/2.0} 0 0" xyz="0 ${left_right*thigh_shoulder_y_offset} 0"/>
                    <geometry>
                        <cylinder length="${thigh_shoulder_length}" radius="${thigh_shoulder_radius}"/>
                    </geometry>
                </collision> -->
        <inertial>
            <origin rpy="0 0 0" xyz="-0.063927 0.057242 0.004729"/>
            <mass value="2.13"/>
            <inertia ixx="0.003260617" ixy="0.003296633" ixz="0.001182035" iyy="0.024261326" iyz="-0.000279689"
                     izz="0.024745032"/>
        </inertial>
    </link>
    <joint name="LH_KFE" type="revolute">
        <origin rpy="0 0 0" xyz="-0.28 0.0797 0"/>
        <parent link="LH_thigh"/>
        <child link="LH_calf"/>
        <axis xyz="0 1 0"/>
        <dynamics damping="0.05" friction="0.01"/>
        <limit effort="60" lower="0.0" upper="1.95476876223365" velocity="20"/>
    </joint>
    <link name="LH_calf">
        <visual>
            <origin rpy="0 0 0" xyz="0 0 0"/>
            <geometry>
                <mesh filename="../meshes/wheel_quadruped/LH_calf.STL" scale="1 1 1"/>
            </geometry>
            <material name="orange"/>
            <color rgba="0.20392 0.20392 0.20392 1"/>
        </visual>
        <collision>
            <origin rpy="0 0.680678408 0" xyz="0.10876 0 -0.08805"/>
            <geometry>
                <box size="0.28 0.023 0.0451"/>
            </geometry>
        </collision>
        <inertial>
            <origin rpy="0 0 0" xyz="0.182894 0.004783 -0.111716"/>
            <mass value="1.123"/>
            <inertia ixx="0.00440324" ixy="-0.000291175" ixz="0.005566403" iyy="0.013523185" iyz="0.000203833"
                     izz="0.009572209"/>
        </inertial>
    </link>
    <joint name="LH_WHL" type="revolute">
        <origin rpy="0 0 0" xyz="0.21441 0.03231 -0.17987"/>
        <parent link="LH_calf"/>
        <child link="LH_wheel"/>
        <axis xyz="0 1 0"/>
        <limit effort="20" lower="-1000" upper="1000" velocity="20"/>
        <dynamics friction="0.1"/>
    </joint>
    <!-- <gazebo reference="${prefix}_WHL">
              <disableFixedJointLumping>true</disableFixedJointLumping>
          </gazebo> -->
    <link name="LH_wheel">
        <visual>
            <origin rpy="0 0 0" xyz="0 0 0"/>
            <geometry>
                <mesh filename="../meshes/wheel_quadruped/LH_wheel.STL"
                      scale="1 1 1"/>
            </geometry>
            <material name="orange"/>
            <color rgba="0.69804 0.69804 0.69804 1"/>
        </visual>
        <collision>
            <origin rpy="1.5707963267948966 0 0" xyz="0 0 0"/>
            <geometry>
                <cylinder length="0.05" radius="0.127"/>
            </geometry>
        </collision>
        <inertial>
            <origin rpy="0 0 0" xyz="7.7e-05 0.001028 -3.3e-05"/>
            <mass value="0.707"/>
            <inertia ixx="0.003059642" ixy="5.1e-08" ixz="-4.28e-07" iyy="0.005866966" iyz="-3.5e-08"
                     izz="0.003063384"/>
        </inertial>
    </link>
    <transmission name="LH_HAA_tran">
        <type>transmission_interface/SimpleTransmission</type>
        <joint name="LH_HAA">
            <hardwareInterface>hardware_interface/EffortJointInterface</hardwareInterface>
        </joint>
        <actuator name="LH_HAA_motor">
            <hardwareInterface>hardware_interface/EffortJointInterface</hardwareInterface>
            <mechanicalReduction>1</mechanicalReduction>
        </actuator>
    </transmission>
    <transmission name="LH_HFE_tran">
        <type>transmission_interface/SimpleTransmission</type>
        <joint name="LH_HFE">
            <hardwareInterface>hardware_interface/EffortJointInterface</hardwareInterface>
        </joint>
        <actuator name="LH_HFE_motor">
            <hardwareInterface>hardware_interface/EffortJointInterface</hardwareInterface>
            <mechanicalReduction>1</mechanicalReduction>
        </actuator>
    </transmission>
    <transmission name="LH_KFE_tran">
        <type>transmission_interface/SimpleTransmission</type>
        <joint name="LH_KFE">
            <hardwareInterface>hardware_interface/EffortJointInterface</hardwareInterface>
        </joint>
        <actuator name="LH_KFE_motor">
            <hardwareInterface>hardware_interface/EffortJointInterface</hardwareInterface>
            <mechanicalReduction>1</mechanicalReduction>
        </actuator>
    </transmission>
    <transmission name="LH_WHL_tran">
        <type>transmission_interface/SimpleTransmission</type>
        <joint name="LH_WHL">
            <hardwareInterface>hardware_interface/EffortJointInterface</hardwareInterface>
        </joint>
        <actuator name="LH_WHL_motor">
            <hardwareInterface>hardware_interface/EffortJointInterface</hardwareInterface>
            <mechanicalReduction>1</mechanicalReduction>
        </actuator>
    </transmission>
    <joint name="RH_HAA" type="revolute">
        <origin rpy="0 0 0" xyz="-0.307 -0.065 -0.07376"/>
        <!-- <origin xyz="${HAA_offset_x*front_hind} ${HAA_offset_y*left_right} ${HAA_offset_z}" rpy="0 0 0"/> -->
        <parent link="base"/>
        <child link="RH_hip"/>
        <axis xyz="1 0 0"/>
        <dynamics damping="0.05" friction="0.01"/>
        <limit effort="60" lower="-0.87" upper="0.87" velocity="20"/>
    </joint>
    <link name="RH_hip">
        <visual>
            <origin rpy="0 0 0" xyz="0 0 0"/>
            <geometry>
                <mesh filename="../meshes/wheel_quadruped/RH_hip.STL" scale="1 1 1"/>
            </geometry>
            <material name="orange"/>
            <color rgba="0.8902 0.8902 0.91373 1"/>
        </visual>
        <!-- <collision>
                    <origin rpy="${pi/2.0} 0 0" xyz="0 0 0"/>
                    <geometry>
                        <cylinder length="${hip_length}" radius="${hip_radius}"/>
                    </geometry>
                </collision> -->
        <inertial>
            <origin rpy="0 0 0" xyz="-0.058399 -0.001551 9e-06"/>
            <mass value="1.06"/>
            <inertia ixx="0.001012701" ixy="1.0667e-05" ixz="2.91e-07" iyy="0.001889263" iyz="-2.19e-07"
                     izz="0.00148239"/>
        </inertial>
    </link>
    <joint name="RH_HFE" type="revolute">
        <origin rpy="0 0 0" xyz="-0.0693 -0.02715 0"/>
        <parent link="RH_hip"/>
        <child link="RH_thigh"/>
        <axis xyz="0 1 0"/>
        <dynamics damping="0.05" friction="0.01"/>
        <limit effort="60" lower="-2.27" upper="1.22" velocity="20"/>
    </joint>
    <link name="RH_thigh">
        <visual>
            <origin rpy="0 0 0" xyz="0 0 0"/>
            <geometry>
                <mesh filename="../meshes/wheel_quadruped/RH_thigh.STL"
                      scale="1 1 1"/>
            </geometry>
            <material name="orange"/>
            <color rgba="0.8902 0.8902 0.91373 1"/>
        </visual>
        <!-- <collision>
                    <origin rpy="0 ${pi/2.0+0.1} 0" xyz="${thigh_x_offset} 0 ${-thigh_length/2.0}"/>
                    <geometry>
                        <box size="${thigh_length} ${thigh_width} ${thigh_height}"/>
                    </geometry>
                </collision>
                <collision>
                    <origin rpy="${pi/2.0} 0 0" xyz="0 ${left_right*thigh_shoulder_y_offset} 0"/>
                    <geometry>
                        <cylinder length="${thigh_shoulder_length}" radius="${thigh_shoulder_radius}"/>
                    </geometry>
                </collision> -->
        <inertial>
            <origin rpy="0 0 0" xyz="-0.063927 -0.057242 0.004729"/>
            <mass value="2.13"/>
            <inertia ixx="0.003260617" ixy="-0.003296633" ixz="0.001182035" iyy="0.024261326" iyz="0.000279689"
                     izz="0.024745032"/>
        </inertial>
    </link>
    <joint name="RH_KFE" type="revolute">
        <origin rpy="0 0 0" xyz="-0.28 -0.0797 0"/>
        <parent link="RH_thigh"/>
        <child link="RH_calf"/>
        <axis xyz="0 1 0"/>
        <dynamics damping="0.05" friction="0.01"/>
        <limit effort="60" lower="0.0" upper="1.95476876223365" velocity="20"/>
    </joint>
    <link name="RH_calf">
        <visual>
            <origin rpy="0 0 0" xyz="0 0 0"/>
            <geometry>
                <mesh filename="../meshes/wheel_quadruped/RH_calf.STL" scale="1 1 1"/>
            </geometry>
            <material name="orange"/>
            <color rgba="0.20392 0.20392 0.20392 1"/>
        </visual>
        <collision>
            <origin rpy="0 0.680678408 0" xyz="0.10876 0 -0.08805"/>
            <geometry>
                <box size="0.28 0.023 0.0451"/>
            </geometry>
        </collision>
        <inertial>
            <origin rpy="0 0 0" xyz="0.182894 -0.004783 -0.111716"/>
            <mass value="1.123"/>
            <inertia ixx="0.00440324" ixy="0.000291175" ixz="0.005566403" iyy="0.013523185" iyz="-0.000203833"
                     izz="0.009572209"/>
        </inertial>
    </link>
    <joint name="RH_WHL" type="revolute">
        <origin rpy="0 0 0" xyz="0.21441 -0.03231 -0.17987"/>
        <parent link="RH_calf"/>
        <child link="RH_wheel"/>
        <axis xyz="0 1 0"/>
        <limit effort="20" lower="-1000" upper="1000" velocity="20"/>
        <dynamics friction="0.1"/>
    </joint>
    <!-- <gazebo reference="${prefix}_WHL">
              <disableFixedJointLumping>true</disableFixedJointLumping>
          </gazebo> -->
    <link name="RH_wheel">
        <visual>
            <origin rpy="0 0 0" xyz="0 0 0"/>
            <geometry>
                <mesh filename="../meshes/wheel_quadruped/RH_wheel.STL"
                      scale="1 1 1"/>
            </geometry>
            <material name="orange"/>
            <color rgba="0.69804 0.69804 0.69804 1"/>
        </visual>
        <collision>
            <origin rpy="1.5707963267948966 0 0" xyz="0 0 0"/>
            <geometry>
                <cylinder length="0.05" radius="0.127"/>
            </geometry>
        </collision>
        <inertial>
            <origin rpy="0 0 0" xyz="7.7e-05 -0.001028 -3.3e-05"/>
            <mass value="0.707"/>
            <inertia ixx="0.003059642" ixy="-5.1e-08" ixz="-4.28e-07" iyy="0.005866966" iyz="3.5e-08"
                     izz="0.003063384"/>
        </inertial>
    </link>
    <transmission name="RH_HAA_tran">
        <type>transmission_interface/SimpleTransmission</type>
        <joint name="RH_HAA">
            <hardwareInterface>hardware_interface/EffortJointInterface</hardwareInterface>
        </joint>
        <actuator name="RH_HAA_motor">
            <hardwareInterface>hardware_interface/EffortJointInterface</hardwareInterface>
            <mechanicalReduction>1</mechanicalReduction>
        </actuator>
    </transmission>
    <transmission name="RH_HFE_tran">
        <type>transmission_interface/SimpleTransmission</type>
        <joint name="RH_HFE">
            <hardwareInterface>hardware_interface/EffortJointInterface</hardwareInterface>
        </joint>
        <actuator name="RH_HFE_motor">
            <hardwareInterface>hardware_interface/EffortJointInterface</hardwareInterface>
            <mechanicalReduction>1</mechanicalReduction>
        </actuator>
    </transmission>
    <transmission name="RH_KFE_tran">
        <type>transmission_interface/SimpleTransmission</type>
        <joint name="RH_KFE">
            <hardwareInterface>hardware_interface/EffortJointInterface</hardwareInterface>
        </joint>
        <actuator name="RH_KFE_motor">
            <hardwareInterface>hardware_interface/EffortJointInterface</hardwareInterface>
            <mechanicalReduction>1</mechanicalReduction>
        </actuator>
    </transmission>
    <transmission name="RH_WHL_tran">
        <type>transmission_interface/SimpleTransmission</type>
        <joint name="RH_WHL">
            <hardwareInterface>hardware_interface/EffortJointInterface</hardwareInterface>
        </joint>
        <actuator name="RH_WHL_motor">
            <hardwareInterface>hardware_interface/EffortJointInterface</hardwareInterface>
            <mechanicalReduction>1</mechanicalReduction>
        </actuator>
    </transmission>

    <joint name="limx_arm_joint" type="fixed">
        <origin rpy="0. 0. 0." xyz="0. 0. 0.0"/>
        <parent link="base"/>
        <child link="limx_arm"/>
    </joint>
    <gazebo reference="limx_arm_joint">
        <disableFixedJointLumping>true</disableFixedJointLumping>
    </gazebo>
    <link name="limx_arm">
    <inertial>
      <origin xyz="-0.004128 -0.000051246 0.0368" rpy="0 0 0" />
      <mass value="1.48" />
      <inertia
        ixx="0.001914"
        ixy="0.0000020344"
        ixz="-0.0000295375"
        iyy="0.0020328"
        iyz="-0.000002793"
        izz="0.0027009" />
    </inertial>
    <visual>
      <origin xyz="0 0 0" rpy="0 0 0" />
      <geometry>
        <mesh filename="../meshes/limx_arm/limx_arm.STL" />
      </geometry>
      <material name="">
        <color rgba="0.792156862745098 0.819607843137255 0.933333333333333 1" />
      </material>
    </visual>
    <collision>
      <origin xyz="0 0 0" rpy="0 0 0" />
      <geometry>
        <mesh filename="../meshes/limx_arm/limx_arm.STL" />
      </geometry>
    </collision>
  </link>

  <joint name="J1" type="revolute">
    <origin xyz="0 0 0" rpy="0 0 0" />
    <parent link="limx_arm" />
    <child link="L1" />
    <axis xyz="0 0 1" />
    <limit lower="-2.97" upper="2.97" effort="75" velocity="38"/>
  </joint>
  <link name="L1">
    <inertial>
      <origin xyz="0.000648785026826915 -1.75983803181417E-05 0.113408403959065" rpy="0 0 0" />
      <mass value="2.38" />
      <inertia
        ixx="0.009788"
        ixy="-0.0000009855"
        ixz="0.0000002033"
        iyy="0.002622"
        iyz="0.000001297"
        izz="0.009287" />
    </inertial>
    <visual>
      <origin xyz="0 0 0" rpy="0 0 0" />
      <geometry>
        <mesh filename="../meshes/limx_arm/L1.STL" />
      </geometry>
      <material name="">
        <color rgba="0.792156862745098 0.819607843137255 0.933333333333333 1" />
      </material>
    </visual>
    <collision>
      <origin xyz="0 0 0" rpy="0 0 0" />
      <geometry>
        <mesh filename="../meshes/limx_arm/L1.STL" />
      </geometry>
    </collision>
  </link>
  

    <joint name="J2" type="revolute">
        <origin xyz="0 0.016 0.14357" rpy="1.5708 0 0" />
        <parent link="L1" />
        <child link="L2" />
        <axis xyz="0 0 1" />
        <limit lower="-1.57" upper="1.57" effort="75" velocity="38"/>
    </joint>
    <link name="L2">
    <inertial>
      <origin xyz="0.0004947 0.1533 0.0162" rpy="0 0 0" />
      <mass value="1.11" />
      <inertia
        ixx="0.01598"
        ixy="0.001113"
        ixz="0.0000004144"
        iyy="0.0017036"
        iyz="0.00003257"
        izz="0.01703" />
    </inertial>
    <visual>
      <origin xyz="0 0 0" rpy="0 0 0" />
      <geometry>
        <mesh filename="../meshes/limx_arm/L2.STL" />
      </geometry>
      <material name="">
        <color rgba="0.792156862745098 0.819607843137255 0.933333333333333 1" />
      </material>
    </visual>
    <collision>
      <origin xyz="0 0 0" rpy="0 0 0" />
      <geometry>
        <mesh filename="../meshes/limx_arm/L2.STL" />
      </geometry>
    </collision>
  </link>
  
  <joint name="J3" type="revolute">
    <origin xyz="-0.022268 0.33734 0.01075" rpy="-3.1416 0 0" />
    <parent link="L2" />
    <child link="L3" />
    <axis xyz="0 0 1" />
    <limit lower="-1.57" upper="1.57" effort="75" velocity="38"/>
  </joint>
  <link name="L3">
    <inertial>
      <origin xyz="0.02491 -0.06391 -0.00006043" rpy="0 0 0" />
      <mass value="1.103" />
      <inertia
        ixx="0.006705"
        ixy="0.003738"
        ixz="-0.000001251"
        iyy="0.003389"
        iyz="0.000003847"
        izz="0.009415" />
    </inertial>
    <visual>
      <origin xyz="0 0 0" rpy="0 0 0" />
      <geometry>
        <mesh filename="../meshes/limx_arm/L3.STL" />
      </geometry>
      <material name="">
        <color rgba="0.792156862745098 0.819607843137255 0.933333333333333 1" />
      </material>
    </visual>
    <collision>
      <origin xyz="0 0 0" rpy="0 0 0" />
      <geometry>
        <mesh filename="../meshes/limx_arm/L3.STL" />
      </geometry>
    </collision>
  </link>
  
  <joint name="J4" type="revolute">
    <origin xyz="0.069334 -0.09437 -0.00525" rpy="-1.5708 0 -1.5708" />
    <parent link="L3" />
    <child link="L4" />
    <axis xyz="0 0 1" />
    <limit lower="-1.57" upper="1.57" effort="20" velocity="38"/>
  </joint>
  <link name="L4">
    <inertial>
      <origin xyz="-0.01475 0.0037164 0.1791" rpy="0 0 0" />
      <mass value="1.023" />
      <inertia
        ixx="0.016036"
        ixy="-0.00005644"
        ixz="-0.0070774"
        iyy="0.021476"
        iyz="-0.0002585"
        izz="0.0061840" />
    </inertial>
    <visual>
      <origin xyz="0 0 0" rpy="0 0 0" />
      <geometry>
        <mesh filename="../meshes/limx_arm/L4.STL" />
      </geometry>
      <material name="">
        <color rgba="0.792156862745098 0.819607843137255 0.933333333333333 1" />
      </material>
    </visual>
    <collision>
      <origin xyz="0 0 0" rpy="0 0 0" />
      <geometry>
        <mesh filename="../meshes/limx_arm/L4.STL" />
      </geometry>
    </collision>
  </link>
  
  <joint name="J5" type="revolute">
    <origin xyz="4.5361E-05 0.027651 0.24727" rpy="1.5708 0.017983 0" />
    <parent link="L4" />
    <child link="L5" />
    <axis xyz="0 0 1" />
    <limit lower="-1.57" upper="1.57" effort="20" velocity="38"/>
  </joint>
  <link name="L5">
    <inertial>
      <origin xyz="0.000020753 0.086297 0.022865" rpy="0 0 0" />
      <mass value="0.872" />
      <inertia
        ixx="0.0015493"
        ixy="-0.0000003432"
        ixz="-0.00000008541"
        iyy="0.0006772"
        iyz="-0.0003375"
        izz="0.001456" />
    </inertial>
    <visual>
      <origin xyz="0 0 0" rpy="0 0 0" />
      <geometry>
        <mesh filename="../meshes/limx_arm/L5.STL" />
      </geometry>
      <material name="">
        <color rgba="0.792156862745098 0.819607843137255 0.933333333333333 1" />
      </material>
    </visual>
    <collision>
      <origin xyz="0 0 0" rpy="0 0 0" />
      <geometry>
        <mesh filename="../meshes/limx_arm/L5.STL" />
      </geometry>
    </collision>
  </link>

  <joint name="J6" type="revolute">
    <origin xyz="-0.0022853 0.12843 0.027657" rpy="-1.5708 0 0.017727" />
    <parent link="L5" />
    <child link="L6" />
    <axis xyz="0 0 1" />
    <limit lower="-1.57" upper="1.57" effort="20" velocity="38"/>
  </joint>
  <link name="L6">
    <inertial>
      <origin xyz="-0.00003796 0.00003159 0.04447" rpy="0 0 0" />
      <mass value="0.668" />
      <inertia
        ixx="0.0004931"
        ixy="0.00000004076"
        ixz="-0.000000857"
        iyy="0.0004929"
        iyz="0.0000004817"
        izz="0.0004169" />
    </inertial>
    <visual>
      <origin xyz="0 0 0" rpy="0 0 0" />
      <geometry>
        <mesh filename="../meshes/limx_arm/L6.STL" />
      </geometry>
      <material name="">
        <color rgba="0.792156862745098 0.819607843137255 0.933333333333333 1" />
      </material>
    </visual>
    <collision>
      <origin xyz="0 0 0" rpy="0 0 0" />
      <geometry>
        <mesh filename="../meshes/limx_arm/L6.STL" />
      </geometry>
    </collision>
  </link>
</robot>